(.venv) (base) PS C:\Python\Prosperous_Bot> cd C:\Python\Prosperous_Bot\src
(.venv) (base) PS C:\Python\Prosperous_Bot\src> pytest -q
C:\Python\prosperous_bot\.venv\Lib\site-packages\coverage\inorout.py:509: CoverageWarning: Module exchange_api was never imported. (module-not-imported)
  self.warn(f"Module {pkg} was never imported.", slug="module-not-imported")
C:\Python\prosperous_bot\.venv\Lib\site-packages\coverage\inorout.py:509: CoverageWarning: Module portfolio_manager was never imported. (module-not-imported)
  self.warn(f"Module {pkg} was never imported.", slug="module-not-imported")
C:\Python\prosperous_bot\.venv\Lib\site-packages\coverage\inorout.py:509: CoverageWarning: Module rebalance_engine was never imported. (module-not-imported)
  self.warn(f"Module {pkg} was never imported.", slug="module-not-imported")
C:\Python\prosperous_bot\.venv\Lib\site-packages\coverage\control.py:915: CoverageWarning: No data was collected. (no-data-collected) 
  self._warn("No data was collected.", slug="no-data-collected")

WARNING: Failed to generate report: No data to report.

C:\Python\prosperous_bot\.venv\Lib\site-packages\pytest_cov\plugin.py:336: CovReportWarning: Failed to generate report: No data to report.

  warnings.warn(CovReportWarning(message), stacklevel=1)

ERROR: Coverage failure: total of 0 is less than fail-under=90

============================================================== ERRORS ===============================================================
_____________________________________________ ERROR collecting src/test_exchange_api.py _____________________________________________ 
..\.venv\Lib\site-packages\pytest_asyncio\plugin.py:754: in _patched_collect
    module = collector.obj
..\.venv\Lib\site-packages\_pytest\python.py:284: in obj
    self._obj = obj = self._getobj()
..\.venv\Lib\site-packages\_pytest\python.py:546: in _getobj
    return importtestmodule(self.path, self.config)
..\.venv\Lib\site-packages\_pytest\python.py:493: in importtestmodule
    mod = import_path(
..\.venv\Lib\site-packages\_pytest\pathlib.py:587: in import_path
    importlib.import_module(module_name)
C:\Users\svsma\AppData\Local\Programs\Python\Python311\Lib\importlib\__init__.py:126: in import_module
    return _bootstrap._gcd_import(name[level:], package, level)
<frozen importlib._bootstrap>:1204: in _gcd_import
    ???
<frozen importlib._bootstrap>:1176: in _find_and_load
    ???
<frozen importlib._bootstrap>:1126: in _find_and_load_unlocked
    ???
<frozen importlib._bootstrap>:241: in _call_with_frames_removed
    ???
<frozen importlib._bootstrap>:1204: in _gcd_import
    ???
<frozen importlib._bootstrap>:1176: in _find_and_load
    ???
<frozen importlib._bootstrap>:1147: in _find_and_load_unlocked
    ???
<frozen importlib._bootstrap>:690: in _load_unlocked
    ???
<frozen importlib._bootstrap_external>:940: in exec_module
    ???
<frozen importlib._bootstrap>:241: in _call_with_frames_removed
    ???
__init__.py:1: in <module>
    self.futures_api = gate_api.FuturesApi(self.api_client)
E   NameError: name 'gate_api' is not defined
========================================================== tests coverage =========================================================== 
__________________________________________ coverage: platform win32, python 3.11.9-final-0 __________________________________________ 

FAIL Required test coverage of 90% not reached. Total coverage: 0.00%
====================================================== short test summary info ======================================================
ERROR test_exchange_api.py - NameError: name 'gate_api' is not defined
!!!!!!!!!!!!!!!!!!!!!!!!!!!!!!!!!!!!!!!!!!!!!! Interrupted: 1 error during collection !!!!!!!!!!!!!!!!!!!!!!!!!!!!!!!!!!!!!!!!!!!!!!! 
(.venv) (base) PS C:\Python\Prosperous_Bot\src> 